Internal Server Error: /api/rss/chanles/datasource/
"GET /api/rss/chanles/datasource/ HTTP/1.1" 500 34
Internal Server Error: /api/rss/chanles/datasource/
"GET /api/rss/chanles/datasource/ HTTP/1.1" 500 34
Internal Server Error: /api/rss/chanles/datasource/
"GET /api/rss/chanles/datasource/ HTTP/1.1" 500 34
Internal Server Error: /api/crud/all/
"GET /api/crud/all/ HTTP/1.1" 500 34
Internal Server Error: /api/crud/all/
"GET /api/crud/all/ HTTP/1.1" 500 34
Internal Server Error: /api/crud/all/
"GET /api/crud/all/ HTTP/1.1" 500 34
Internal Server Error: /api/crud/all/
"GET /api/crud/all/ HTTP/1.1" 500 34
Internal Server Error: /api/crud/all/
"GET /api/crud/all/ HTTP/1.1" 500 34
Internal Server Error: /api/crud/all/
"GET /api/crud/all/ HTTP/1.1" 500 34
Internal Server Error: /api/crud/all/
"GET /api/crud/all/ HTTP/1.1" 500 34
Internal Server Error: /api/crud/all/
"GET /api/crud/all/ HTTP/1.1" 500 34
Internal Server Error: /api/crud/all/
"GET /api/crud/all/ HTTP/1.1" 500 34
Internal Server Error: /api/crud/all/
"GET /api/crud/all/ HTTP/1.1" 500 34
Internal Server Error: /api/crud/all/
"GET /api/crud/all/ HTTP/1.1" 500 34
Internal Server Error: /api/rss/chanles/datasource/
Traceback (most recent call last):
  File "C:\Users\equihua\AppData\Local\Programs\Python\Python38-32\lib\site-packages\django\core\handlers\exception.py", line 34, in inner
    response = get_response(request)
  File "C:\Users\equihua\AppData\Local\Programs\Python\Python38-32\lib\site-packages\django\core\handlers\base.py", line 115, in _get_response
    response = self.process_exception_by_middleware(e, request)
  File "C:\Users\equihua\AppData\Local\Programs\Python\Python38-32\lib\site-packages\django\core\handlers\base.py", line 113, in _get_response
    response = wrapped_callback(request, *callback_args, **callback_kwargs)
  File "C:\Users\equihua\AppData\Local\Programs\Python\Python38-32\lib\site-packages\django\views\decorators\csrf.py", line 54, in wrapped_view
    return view_func(*args, **kwargs)
  File "C:\Users\equihua\AppData\Local\Programs\Python\Python38-32\lib\site-packages\django\views\generic\base.py", line 71, in view
    return self.dispatch(request, *args, **kwargs)
  File "C:\Users\equihua\AppData\Local\Programs\Python\Python38-32\lib\site-packages\rest_framework\views.py", line 507, in dispatch
    self.response = self.finalize_response(request, response, *args, **kwargs)
  File "C:\Users\equihua\AppData\Local\Programs\Python\Python38-32\lib\site-packages\rest_framework\views.py", line 419, in finalize_response
    assert isinstance(response, HttpResponseBase), (
AssertionError: Expected a `Response`, `HttpResponse` or `HttpStreamingResponse` to be returned from the view, but received a `<class 'NoneType'>`
"GET /api/rss/chanles/datasource/ HTTP/1.1" 500 81327
Internal Server Error: /api/rss/chanles/datasource/
"POST /api/rss/chanles/datasource/ HTTP/1.1" 500 34
Internal Server Error: /
Traceback (most recent call last):
  File "C:\Users\equihua\AppData\Local\Programs\Python\Python38-32\lib\site-packages\django\core\handlers\exception.py", line 34, in inner
    response = get_response(request)
  File "C:\Users\equihua\AppData\Local\Programs\Python\Python38-32\lib\site-packages\django\core\handlers\base.py", line 115, in _get_response
    response = self.process_exception_by_middleware(e, request)
  File "C:\Users\equihua\AppData\Local\Programs\Python\Python38-32\lib\site-packages\django\core\handlers\base.py", line 113, in _get_response
    response = wrapped_callback(request, *callback_args, **callback_kwargs)
  File "C:\Users\equihua\Documents\testfacturedo\rssreader\rssapp\views.py", line 12, in index_view
    return render(request, "index.html", ctx)
  File "C:\Users\equihua\AppData\Local\Programs\Python\Python38-32\lib\site-packages\django\shortcuts.py", line 36, in render
    content = loader.render_to_string(template_name, context, request, using=using)
  File "C:\Users\equihua\AppData\Local\Programs\Python\Python38-32\lib\site-packages\django\template\loader.py", line 61, in render_to_string
    template = get_template(template_name, using=using)
  File "C:\Users\equihua\AppData\Local\Programs\Python\Python38-32\lib\site-packages\django\template\loader.py", line 15, in get_template
    return engine.get_template(template_name)
  File "C:\Users\equihua\AppData\Local\Programs\Python\Python38-32\lib\site-packages\django\template\backends\django.py", line 34, in get_template
    return Template(self.engine.get_template(template_name), self)
  File "C:\Users\equihua\AppData\Local\Programs\Python\Python38-32\lib\site-packages\django\template\engine.py", line 143, in get_template
    template, origin = self.find_template(template_name)
  File "C:\Users\equihua\AppData\Local\Programs\Python\Python38-32\lib\site-packages\django\template\engine.py", line 125, in find_template
    template = loader.get_template(name, skip=skip)
  File "C:\Users\equihua\AppData\Local\Programs\Python\Python38-32\lib\site-packages\django\template\loaders\base.py", line 29, in get_template
    return Template(
  File "C:\Users\equihua\AppData\Local\Programs\Python\Python38-32\lib\site-packages\django\template\base.py", line 156, in __init__
    self.nodelist = self.compile_nodelist()
  File "C:\Users\equihua\AppData\Local\Programs\Python\Python38-32\lib\site-packages\django\template\base.py", line 194, in compile_nodelist
    return parser.parse()
  File "C:\Users\equihua\AppData\Local\Programs\Python\Python38-32\lib\site-packages\django\template\base.py", line 449, in parse
    raise self.error(token, e)
  File "C:\Users\equihua\AppData\Local\Programs\Python\Python38-32\lib\site-packages\django\template\base.py", line 447, in parse
    filter_expression = self.compile_filter(token.contents)
  File "C:\Users\equihua\AppData\Local\Programs\Python\Python38-32\lib\site-packages\django\template\base.py", line 563, in compile_filter
    return FilterExpression(token, self)
  File "C:\Users\equihua\AppData\Local\Programs\Python\Python38-32\lib\site-packages\django\template\base.py", line 662, in __init__
    raise TemplateSyntaxError("Could not parse the remainder: '%s' "
django.template.exceptions.TemplateSyntaxError: Could not parse the remainder: '("{{user_id' from 'localStorage.setItem("{{user_id'
"GET / HTTP/1.1" 500 143684
Internal Server Error: /api/rss/chanles/users/
Traceback (most recent call last):
  File "C:\Users\equihua\AppData\Local\Programs\Python\Python38-32\lib\site-packages\django\core\handlers\exception.py", line 34, in inner
    response = get_response(request)
  File "C:\Users\equihua\AppData\Local\Programs\Python\Python38-32\lib\site-packages\django\core\handlers\base.py", line 115, in _get_response
    response = self.process_exception_by_middleware(e, request)
  File "C:\Users\equihua\AppData\Local\Programs\Python\Python38-32\lib\site-packages\django\core\handlers\base.py", line 113, in _get_response
    response = wrapped_callback(request, *callback_args, **callback_kwargs)
  File "C:\Users\equihua\AppData\Local\Programs\Python\Python38-32\lib\site-packages\django\views\decorators\csrf.py", line 54, in wrapped_view
    return view_func(*args, **kwargs)
  File "C:\Users\equihua\AppData\Local\Programs\Python\Python38-32\lib\site-packages\django\views\generic\base.py", line 71, in view
    return self.dispatch(request, *args, **kwargs)
  File "C:\Users\equihua\AppData\Local\Programs\Python\Python38-32\lib\site-packages\rest_framework\views.py", line 505, in dispatch
    response = self.handle_exception(exc)
  File "C:\Users\equihua\AppData\Local\Programs\Python\Python38-32\lib\site-packages\rest_framework\views.py", line 465, in handle_exception
    self.raise_uncaught_exception(exc)
  File "C:\Users\equihua\AppData\Local\Programs\Python\Python38-32\lib\site-packages\rest_framework\views.py", line 476, in raise_uncaught_exception
    raise exc
  File "C:\Users\equihua\AppData\Local\Programs\Python\Python38-32\lib\site-packages\rest_framework\views.py", line 502, in dispatch
    response = handler(request, *args, **kwargs)
  File "C:\Users\equihua\AppData\Local\Programs\Python\Python38-32\lib\site-packages\rest_framework\decorators.py", line 50, in handler
    return func(*args, **kwargs)
  File "C:\Users\equihua\Documents\testfacturedo\rssreader\rssapp\api.py", line 209, in get_channel_users
    channels_ids = user_id.channels_ids
AttributeError: 'str' object has no attribute 'channels_ids'
"POST /api/rss/chanles/users/ HTTP/1.1" 500 17681
Internal Server Error: /api/rss/chanles/users/
Traceback (most recent call last):
  File "C:\Users\equihua\AppData\Local\Programs\Python\Python38-32\lib\site-packages\django\core\handlers\exception.py", line 34, in inner
    response = get_response(request)
  File "C:\Users\equihua\AppData\Local\Programs\Python\Python38-32\lib\site-packages\django\core\handlers\base.py", line 115, in _get_response
    response = self.process_exception_by_middleware(e, request)
  File "C:\Users\equihua\AppData\Local\Programs\Python\Python38-32\lib\site-packages\django\core\handlers\base.py", line 113, in _get_response
    response = wrapped_callback(request, *callback_args, **callback_kwargs)
  File "C:\Users\equihua\AppData\Local\Programs\Python\Python38-32\lib\site-packages\django\views\decorators\csrf.py", line 54, in wrapped_view
    return view_func(*args, **kwargs)
  File "C:\Users\equihua\AppData\Local\Programs\Python\Python38-32\lib\site-packages\django\views\generic\base.py", line 71, in view
    return self.dispatch(request, *args, **kwargs)
  File "C:\Users\equihua\AppData\Local\Programs\Python\Python38-32\lib\site-packages\rest_framework\views.py", line 505, in dispatch
    response = self.handle_exception(exc)
  File "C:\Users\equihua\AppData\Local\Programs\Python\Python38-32\lib\site-packages\rest_framework\views.py", line 465, in handle_exception
    self.raise_uncaught_exception(exc)
  File "C:\Users\equihua\AppData\Local\Programs\Python\Python38-32\lib\site-packages\rest_framework\views.py", line 476, in raise_uncaught_exception
    raise exc
  File "C:\Users\equihua\AppData\Local\Programs\Python\Python38-32\lib\site-packages\rest_framework\views.py", line 502, in dispatch
    response = handler(request, *args, **kwargs)
  File "C:\Users\equihua\AppData\Local\Programs\Python\Python38-32\lib\site-packages\rest_framework\decorators.py", line 50, in handler
    return func(*args, **kwargs)
  File "C:\Users\equihua\Documents\testfacturedo\rssreader\rssapp\api.py", line 209, in get_channel_users
    channels_ids = user_id.channels_ids
AttributeError: 'str' object has no attribute 'channels_ids'
"POST /api/rss/chanles/users/ HTTP/1.1" 500 17681
Internal Server Error: /api/rss/chanles/users/
Traceback (most recent call last):
  File "C:\Users\equihua\AppData\Local\Programs\Python\Python38-32\lib\site-packages\django\core\handlers\exception.py", line 34, in inner
    response = get_response(request)
  File "C:\Users\equihua\AppData\Local\Programs\Python\Python38-32\lib\site-packages\django\core\handlers\base.py", line 115, in _get_response
    response = self.process_exception_by_middleware(e, request)
  File "C:\Users\equihua\AppData\Local\Programs\Python\Python38-32\lib\site-packages\django\core\handlers\base.py", line 113, in _get_response
    response = wrapped_callback(request, *callback_args, **callback_kwargs)
  File "C:\Users\equihua\AppData\Local\Programs\Python\Python38-32\lib\site-packages\django\views\decorators\csrf.py", line 54, in wrapped_view
    return view_func(*args, **kwargs)
  File "C:\Users\equihua\AppData\Local\Programs\Python\Python38-32\lib\site-packages\django\views\generic\base.py", line 71, in view
    return self.dispatch(request, *args, **kwargs)
  File "C:\Users\equihua\AppData\Local\Programs\Python\Python38-32\lib\site-packages\rest_framework\views.py", line 505, in dispatch
    response = self.handle_exception(exc)
  File "C:\Users\equihua\AppData\Local\Programs\Python\Python38-32\lib\site-packages\rest_framework\views.py", line 465, in handle_exception
    self.raise_uncaught_exception(exc)
  File "C:\Users\equihua\AppData\Local\Programs\Python\Python38-32\lib\site-packages\rest_framework\views.py", line 476, in raise_uncaught_exception
    raise exc
  File "C:\Users\equihua\AppData\Local\Programs\Python\Python38-32\lib\site-packages\rest_framework\views.py", line 502, in dispatch
    response = handler(request, *args, **kwargs)
  File "C:\Users\equihua\AppData\Local\Programs\Python\Python38-32\lib\site-packages\rest_framework\decorators.py", line 50, in handler
    return func(*args, **kwargs)
  File "C:\Users\equihua\Documents\testfacturedo\rssreader\rssapp\api.py", line 209, in get_channel_users
    channels_ids = user_id.channels_ids
AttributeError: 'str' object has no attribute 'channels_ids'
"POST /api/rss/chanles/users/ HTTP/1.1" 500 17681
Internal Server Error: /api/rss/chanles/users/
Traceback (most recent call last):
  File "C:\Users\equihua\AppData\Local\Programs\Python\Python38-32\lib\site-packages\django\core\handlers\exception.py", line 34, in inner
    response = get_response(request)
  File "C:\Users\equihua\AppData\Local\Programs\Python\Python38-32\lib\site-packages\django\core\handlers\base.py", line 115, in _get_response
    response = self.process_exception_by_middleware(e, request)
  File "C:\Users\equihua\AppData\Local\Programs\Python\Python38-32\lib\site-packages\django\core\handlers\base.py", line 113, in _get_response
    response = wrapped_callback(request, *callback_args, **callback_kwargs)
  File "C:\Users\equihua\AppData\Local\Programs\Python\Python38-32\lib\site-packages\django\views\decorators\csrf.py", line 54, in wrapped_view
    return view_func(*args, **kwargs)
  File "C:\Users\equihua\AppData\Local\Programs\Python\Python38-32\lib\site-packages\django\views\generic\base.py", line 71, in view
    return self.dispatch(request, *args, **kwargs)
  File "C:\Users\equihua\AppData\Local\Programs\Python\Python38-32\lib\site-packages\rest_framework\views.py", line 505, in dispatch
    response = self.handle_exception(exc)
  File "C:\Users\equihua\AppData\Local\Programs\Python\Python38-32\lib\site-packages\rest_framework\views.py", line 465, in handle_exception
    self.raise_uncaught_exception(exc)
  File "C:\Users\equihua\AppData\Local\Programs\Python\Python38-32\lib\site-packages\rest_framework\views.py", line 476, in raise_uncaught_exception
    raise exc
  File "C:\Users\equihua\AppData\Local\Programs\Python\Python38-32\lib\site-packages\rest_framework\views.py", line 502, in dispatch
    response = handler(request, *args, **kwargs)
  File "C:\Users\equihua\AppData\Local\Programs\Python\Python38-32\lib\site-packages\rest_framework\decorators.py", line 50, in handler
    return func(*args, **kwargs)
  File "C:\Users\equihua\Documents\testfacturedo\rssreader\rssapp\api.py", line 209, in get_channel_users
    channels_ids = user_id.channels_ids
AttributeError: 'str' object has no attribute 'channels_ids'
"POST /api/rss/chanles/users/ HTTP/1.1" 500 17681
Internal Server Error: /api/rss/chanles/users/
Traceback (most recent call last):
  File "C:\Users\equihua\AppData\Local\Programs\Python\Python38-32\lib\site-packages\django\core\handlers\exception.py", line 34, in inner
    response = get_response(request)
  File "C:\Users\equihua\AppData\Local\Programs\Python\Python38-32\lib\site-packages\django\core\handlers\base.py", line 115, in _get_response
    response = self.process_exception_by_middleware(e, request)
  File "C:\Users\equihua\AppData\Local\Programs\Python\Python38-32\lib\site-packages\django\core\handlers\base.py", line 113, in _get_response
    response = wrapped_callback(request, *callback_args, **callback_kwargs)
  File "C:\Users\equihua\AppData\Local\Programs\Python\Python38-32\lib\site-packages\django\views\decorators\csrf.py", line 54, in wrapped_view
    return view_func(*args, **kwargs)
  File "C:\Users\equihua\AppData\Local\Programs\Python\Python38-32\lib\site-packages\django\views\generic\base.py", line 71, in view
    return self.dispatch(request, *args, **kwargs)
  File "C:\Users\equihua\AppData\Local\Programs\Python\Python38-32\lib\site-packages\rest_framework\views.py", line 505, in dispatch
    response = self.handle_exception(exc)
  File "C:\Users\equihua\AppData\Local\Programs\Python\Python38-32\lib\site-packages\rest_framework\views.py", line 465, in handle_exception
    self.raise_uncaught_exception(exc)
  File "C:\Users\equihua\AppData\Local\Programs\Python\Python38-32\lib\site-packages\rest_framework\views.py", line 476, in raise_uncaught_exception
    raise exc
  File "C:\Users\equihua\AppData\Local\Programs\Python\Python38-32\lib\site-packages\rest_framework\views.py", line 502, in dispatch
    response = handler(request, *args, **kwargs)
  File "C:\Users\equihua\AppData\Local\Programs\Python\Python38-32\lib\site-packages\rest_framework\decorators.py", line 50, in handler
    return func(*args, **kwargs)
  File "C:\Users\equihua\Documents\testfacturedo\rssreader\rssapp\api.py", line 209, in get_channel_users
    channels_ids = user_id.channels_ids
AttributeError: 'int' object has no attribute 'channels_ids'
"POST /api/rss/chanles/users/ HTTP/1.1" 500 17046
Internal Server Error: /api/rss/chanles/users/
Traceback (most recent call last):
  File "C:\Users\equihua\AppData\Local\Programs\Python\Python38-32\lib\site-packages\django\core\handlers\exception.py", line 34, in inner
    response = get_response(request)
  File "C:\Users\equihua\AppData\Local\Programs\Python\Python38-32\lib\site-packages\django\core\handlers\base.py", line 115, in _get_response
    response = self.process_exception_by_middleware(e, request)
  File "C:\Users\equihua\AppData\Local\Programs\Python\Python38-32\lib\site-packages\django\core\handlers\base.py", line 113, in _get_response
    response = wrapped_callback(request, *callback_args, **callback_kwargs)
  File "C:\Users\equihua\AppData\Local\Programs\Python\Python38-32\lib\site-packages\django\views\decorators\csrf.py", line 54, in wrapped_view
    return view_func(*args, **kwargs)
  File "C:\Users\equihua\AppData\Local\Programs\Python\Python38-32\lib\site-packages\django\views\generic\base.py", line 71, in view
    return self.dispatch(request, *args, **kwargs)
  File "C:\Users\equihua\AppData\Local\Programs\Python\Python38-32\lib\site-packages\rest_framework\views.py", line 505, in dispatch
    response = self.handle_exception(exc)
  File "C:\Users\equihua\AppData\Local\Programs\Python\Python38-32\lib\site-packages\rest_framework\views.py", line 465, in handle_exception
    self.raise_uncaught_exception(exc)
  File "C:\Users\equihua\AppData\Local\Programs\Python\Python38-32\lib\site-packages\rest_framework\views.py", line 476, in raise_uncaught_exception
    raise exc
  File "C:\Users\equihua\AppData\Local\Programs\Python\Python38-32\lib\site-packages\rest_framework\views.py", line 502, in dispatch
    response = handler(request, *args, **kwargs)
  File "C:\Users\equihua\AppData\Local\Programs\Python\Python38-32\lib\site-packages\rest_framework\decorators.py", line 50, in handler
    return func(*args, **kwargs)
  File "C:\Users\equihua\Documents\testfacturedo\rssreader\rssapp\api.py", line 209, in get_channel_users
    user = Users.objecys.filter(id=user_id).first()
AttributeError: type object 'Users' has no attribute 'objecys'
"POST /api/rss/chanles/users/ HTTP/1.1" 500 17062
Internal Server Error: /api/rss/chanles/users/
Traceback (most recent call last):
  File "C:\Users\equihua\AppData\Local\Programs\Python\Python38-32\lib\site-packages\django\core\handlers\exception.py", line 34, in inner
    response = get_response(request)
  File "C:\Users\equihua\AppData\Local\Programs\Python\Python38-32\lib\site-packages\django\core\handlers\base.py", line 115, in _get_response
    response = self.process_exception_by_middleware(e, request)
  File "C:\Users\equihua\AppData\Local\Programs\Python\Python38-32\lib\site-packages\django\core\handlers\base.py", line 113, in _get_response
    response = wrapped_callback(request, *callback_args, **callback_kwargs)
  File "C:\Users\equihua\AppData\Local\Programs\Python\Python38-32\lib\site-packages\django\views\decorators\csrf.py", line 54, in wrapped_view
    return view_func(*args, **kwargs)
  File "C:\Users\equihua\AppData\Local\Programs\Python\Python38-32\lib\site-packages\django\views\generic\base.py", line 71, in view
    return self.dispatch(request, *args, **kwargs)
  File "C:\Users\equihua\AppData\Local\Programs\Python\Python38-32\lib\site-packages\rest_framework\views.py", line 505, in dispatch
    response = self.handle_exception(exc)
  File "C:\Users\equihua\AppData\Local\Programs\Python\Python38-32\lib\site-packages\rest_framework\views.py", line 465, in handle_exception
    self.raise_uncaught_exception(exc)
  File "C:\Users\equihua\AppData\Local\Programs\Python\Python38-32\lib\site-packages\rest_framework\views.py", line 476, in raise_uncaught_exception
    raise exc
  File "C:\Users\equihua\AppData\Local\Programs\Python\Python38-32\lib\site-packages\rest_framework\views.py", line 502, in dispatch
    response = handler(request, *args, **kwargs)
  File "C:\Users\equihua\AppData\Local\Programs\Python\Python38-32\lib\site-packages\rest_framework\decorators.py", line 50, in handler
    return func(*args, **kwargs)
  File "C:\Users\equihua\Documents\testfacturedo\rssreader\rssapp\api.py", line 210, in get_channel_users
    channels_ids = user.channels_ids
AttributeError: 'NoneType' object has no attribute 'channels_ids'
"POST /api/rss/chanles/users/ HTTP/1.1" 500 17053
Internal Server Error: /api/rss/chanles/users/
Traceback (most recent call last):
  File "C:\Users\equihua\AppData\Local\Programs\Python\Python38-32\lib\site-packages\django\core\handlers\exception.py", line 34, in inner
    response = get_response(request)
  File "C:\Users\equihua\AppData\Local\Programs\Python\Python38-32\lib\site-packages\django\core\handlers\base.py", line 115, in _get_response
    response = self.process_exception_by_middleware(e, request)
  File "C:\Users\equihua\AppData\Local\Programs\Python\Python38-32\lib\site-packages\django\core\handlers\base.py", line 113, in _get_response
    response = wrapped_callback(request, *callback_args, **callback_kwargs)
  File "C:\Users\equihua\AppData\Local\Programs\Python\Python38-32\lib\site-packages\django\views\decorators\csrf.py", line 54, in wrapped_view
    return view_func(*args, **kwargs)
  File "C:\Users\equihua\AppData\Local\Programs\Python\Python38-32\lib\site-packages\django\views\generic\base.py", line 71, in view
    return self.dispatch(request, *args, **kwargs)
  File "C:\Users\equihua\AppData\Local\Programs\Python\Python38-32\lib\site-packages\rest_framework\views.py", line 505, in dispatch
    response = self.handle_exception(exc)
  File "C:\Users\equihua\AppData\Local\Programs\Python\Python38-32\lib\site-packages\rest_framework\views.py", line 465, in handle_exception
    self.raise_uncaught_exception(exc)
  File "C:\Users\equihua\AppData\Local\Programs\Python\Python38-32\lib\site-packages\rest_framework\views.py", line 476, in raise_uncaught_exception
    raise exc
  File "C:\Users\equihua\AppData\Local\Programs\Python\Python38-32\lib\site-packages\rest_framework\views.py", line 502, in dispatch
    response = handler(request, *args, **kwargs)
  File "C:\Users\equihua\AppData\Local\Programs\Python\Python38-32\lib\site-packages\rest_framework\decorators.py", line 50, in handler
    return func(*args, **kwargs)
  File "C:\Users\equihua\Documents\testfacturedo\rssreader\rssapp\api.py", line 211, in get_channel_users
    channels_exclude_ids = RssChannel.objects.exclude(id__in=channels_ids)
  File "C:\Users\equihua\AppData\Local\Programs\Python\Python38-32\lib\site-packages\django\db\models\manager.py", line 82, in manager_method
    return getattr(self.get_queryset(), name)(*args, **kwargs)
  File "C:\Users\equihua\AppData\Local\Programs\Python\Python38-32\lib\site-packages\django\db\models\query.py", line 899, in exclude
    return self._filter_or_exclude(True, *args, **kwargs)
  File "C:\Users\equihua\AppData\Local\Programs\Python\Python38-32\lib\site-packages\django\db\models\query.py", line 908, in _filter_or_exclude
    clone.query.add_q(~Q(*args, **kwargs))
  File "C:\Users\equihua\AppData\Local\Programs\Python\Python38-32\lib\site-packages\django\db\models\sql\query.py", line 1290, in add_q
    clause, _ = self._add_q(q_object, self.used_aliases)
  File "C:\Users\equihua\AppData\Local\Programs\Python\Python38-32\lib\site-packages\django\db\models\sql\query.py", line 1315, in _add_q
    child_clause, needed_inner = self.build_filter(
  File "C:\Users\equihua\AppData\Local\Programs\Python\Python38-32\lib\site-packages\django\db\models\sql\query.py", line 1251, in build_filter
    condition = self.build_lookup(lookups, col, value)
  File "C:\Users\equihua\AppData\Local\Programs\Python\Python38-32\lib\site-packages\django\db\models\sql\query.py", line 1116, in build_lookup
    lookup = lookup_class(lhs, rhs)
  File "C:\Users\equihua\AppData\Local\Programs\Python\Python38-32\lib\site-packages\django\db\models\lookups.py", line 20, in __init__
    self.rhs = self.get_prep_lookup()
  File "C:\Users\equihua\AppData\Local\Programs\Python\Python38-32\lib\site-packages\django\db\models\lookups.py", line 204, in get_prep_lookup
    for rhs_value in self.rhs:
TypeError: 'ManyRelatedManager' object is not iterable
"POST /api/rss/chanles/users/ HTTP/1.1" 500 18777
Internal Server Error: /api/rss/chanles/users/
Traceback (most recent call last):
  File "C:\Users\equihua\AppData\Local\Programs\Python\Python38-32\lib\site-packages\django\core\handlers\exception.py", line 34, in inner
    response = get_response(request)
  File "C:\Users\equihua\AppData\Local\Programs\Python\Python38-32\lib\site-packages\django\core\handlers\base.py", line 115, in _get_response
    response = self.process_exception_by_middleware(e, request)
  File "C:\Users\equihua\AppData\Local\Programs\Python\Python38-32\lib\site-packages\django\core\handlers\base.py", line 113, in _get_response
    response = wrapped_callback(request, *callback_args, **callback_kwargs)
  File "C:\Users\equihua\AppData\Local\Programs\Python\Python38-32\lib\site-packages\django\views\decorators\csrf.py", line 54, in wrapped_view
    return view_func(*args, **kwargs)
  File "C:\Users\equihua\AppData\Local\Programs\Python\Python38-32\lib\site-packages\django\views\generic\base.py", line 71, in view
    return self.dispatch(request, *args, **kwargs)
  File "C:\Users\equihua\AppData\Local\Programs\Python\Python38-32\lib\site-packages\rest_framework\views.py", line 505, in dispatch
    response = self.handle_exception(exc)
  File "C:\Users\equihua\AppData\Local\Programs\Python\Python38-32\lib\site-packages\rest_framework\views.py", line 465, in handle_exception
    self.raise_uncaught_exception(exc)
  File "C:\Users\equihua\AppData\Local\Programs\Python\Python38-32\lib\site-packages\rest_framework\views.py", line 476, in raise_uncaught_exception
    raise exc
  File "C:\Users\equihua\AppData\Local\Programs\Python\Python38-32\lib\site-packages\rest_framework\views.py", line 502, in dispatch
    response = handler(request, *args, **kwargs)
  File "C:\Users\equihua\AppData\Local\Programs\Python\Python38-32\lib\site-packages\rest_framework\decorators.py", line 50, in handler
    return func(*args, **kwargs)
  File "C:\Users\equihua\Documents\testfacturedo\rssreader\rssapp\api.py", line 213, in get_channel_users
    channels_exclude_ids = RssChannel.objects.exclude(id__in=channels_ids)
  File "C:\Users\equihua\AppData\Local\Programs\Python\Python38-32\lib\site-packages\django\db\models\manager.py", line 82, in manager_method
    return getattr(self.get_queryset(), name)(*args, **kwargs)
  File "C:\Users\equihua\AppData\Local\Programs\Python\Python38-32\lib\site-packages\django\db\models\query.py", line 899, in exclude
    return self._filter_or_exclude(True, *args, **kwargs)
  File "C:\Users\equihua\AppData\Local\Programs\Python\Python38-32\lib\site-packages\django\db\models\query.py", line 908, in _filter_or_exclude
    clone.query.add_q(~Q(*args, **kwargs))
  File "C:\Users\equihua\AppData\Local\Programs\Python\Python38-32\lib\site-packages\django\db\models\sql\query.py", line 1290, in add_q
    clause, _ = self._add_q(q_object, self.used_aliases)
  File "C:\Users\equihua\AppData\Local\Programs\Python\Python38-32\lib\site-packages\django\db\models\sql\query.py", line 1315, in _add_q
    child_clause, needed_inner = self.build_filter(
  File "C:\Users\equihua\AppData\Local\Programs\Python\Python38-32\lib\site-packages\django\db\models\sql\query.py", line 1251, in build_filter
    condition = self.build_lookup(lookups, col, value)
  File "C:\Users\equihua\AppData\Local\Programs\Python\Python38-32\lib\site-packages\django\db\models\sql\query.py", line 1116, in build_lookup
    lookup = lookup_class(lhs, rhs)
  File "C:\Users\equihua\AppData\Local\Programs\Python\Python38-32\lib\site-packages\django\db\models\lookups.py", line 20, in __init__
    self.rhs = self.get_prep_lookup()
  File "C:\Users\equihua\AppData\Local\Programs\Python\Python38-32\lib\site-packages\django\db\models\lookups.py", line 204, in get_prep_lookup
    for rhs_value in self.rhs:
TypeError: 'ManyRelatedManager' object is not iterable
"POST /api/rss/chanles/users/ HTTP/1.1" 500 18777
Internal Server Error: /api/rss/chanles/users/
Traceback (most recent call last):
  File "C:\Users\equihua\AppData\Local\Programs\Python\Python38-32\lib\site-packages\django\core\handlers\exception.py", line 34, in inner
    response = get_response(request)
  File "C:\Users\equihua\AppData\Local\Programs\Python\Python38-32\lib\site-packages\django\core\handlers\base.py", line 115, in _get_response
    response = self.process_exception_by_middleware(e, request)
  File "C:\Users\equihua\AppData\Local\Programs\Python\Python38-32\lib\site-packages\django\core\handlers\base.py", line 113, in _get_response
    response = wrapped_callback(request, *callback_args, **callback_kwargs)
  File "C:\Users\equihua\AppData\Local\Programs\Python\Python38-32\lib\site-packages\django\views\decorators\csrf.py", line 54, in wrapped_view
    return view_func(*args, **kwargs)
  File "C:\Users\equihua\AppData\Local\Programs\Python\Python38-32\lib\site-packages\django\views\generic\base.py", line 71, in view
    return self.dispatch(request, *args, **kwargs)
  File "C:\Users\equihua\AppData\Local\Programs\Python\Python38-32\lib\site-packages\rest_framework\views.py", line 505, in dispatch
    response = self.handle_exception(exc)
  File "C:\Users\equihua\AppData\Local\Programs\Python\Python38-32\lib\site-packages\rest_framework\views.py", line 465, in handle_exception
    self.raise_uncaught_exception(exc)
  File "C:\Users\equihua\AppData\Local\Programs\Python\Python38-32\lib\site-packages\rest_framework\views.py", line 476, in raise_uncaught_exception
    raise exc
  File "C:\Users\equihua\AppData\Local\Programs\Python\Python38-32\lib\site-packages\rest_framework\views.py", line 502, in dispatch
    response = handler(request, *args, **kwargs)
  File "C:\Users\equihua\AppData\Local\Programs\Python\Python38-32\lib\site-packages\rest_framework\decorators.py", line 50, in handler
    return func(*args, **kwargs)
  File "C:\Users\equihua\Documents\testfacturedo\rssreader\rssapp\api.py", line 213, in get_channel_users
    channels_exclude_ids = RssChannel.objects.exclude(id__in=channels_ids)
  File "C:\Users\equihua\AppData\Local\Programs\Python\Python38-32\lib\site-packages\django\db\models\manager.py", line 82, in manager_method
    return getattr(self.get_queryset(), name)(*args, **kwargs)
  File "C:\Users\equihua\AppData\Local\Programs\Python\Python38-32\lib\site-packages\django\db\models\query.py", line 899, in exclude
    return self._filter_or_exclude(True, *args, **kwargs)
  File "C:\Users\equihua\AppData\Local\Programs\Python\Python38-32\lib\site-packages\django\db\models\query.py", line 908, in _filter_or_exclude
    clone.query.add_q(~Q(*args, **kwargs))
  File "C:\Users\equihua\AppData\Local\Programs\Python\Python38-32\lib\site-packages\django\db\models\sql\query.py", line 1290, in add_q
    clause, _ = self._add_q(q_object, self.used_aliases)
  File "C:\Users\equihua\AppData\Local\Programs\Python\Python38-32\lib\site-packages\django\db\models\sql\query.py", line 1315, in _add_q
    child_clause, needed_inner = self.build_filter(
  File "C:\Users\equihua\AppData\Local\Programs\Python\Python38-32\lib\site-packages\django\db\models\sql\query.py", line 1251, in build_filter
    condition = self.build_lookup(lookups, col, value)
  File "C:\Users\equihua\AppData\Local\Programs\Python\Python38-32\lib\site-packages\django\db\models\sql\query.py", line 1116, in build_lookup
    lookup = lookup_class(lhs, rhs)
  File "C:\Users\equihua\AppData\Local\Programs\Python\Python38-32\lib\site-packages\django\db\models\lookups.py", line 20, in __init__
    self.rhs = self.get_prep_lookup()
  File "C:\Users\equihua\AppData\Local\Programs\Python\Python38-32\lib\site-packages\django\db\models\lookups.py", line 204, in get_prep_lookup
    for rhs_value in self.rhs:
TypeError: 'ManyRelatedManager' object is not iterable
"POST /api/rss/chanles/users/ HTTP/1.1" 500 18777
Internal Server Error: /api/rss/chanles/users/
Traceback (most recent call last):
  File "C:\Users\equihua\AppData\Local\Programs\Python\Python38-32\lib\site-packages\django\core\handlers\exception.py", line 34, in inner
    response = get_response(request)
  File "C:\Users\equihua\AppData\Local\Programs\Python\Python38-32\lib\site-packages\django\core\handlers\base.py", line 115, in _get_response
    response = self.process_exception_by_middleware(e, request)
  File "C:\Users\equihua\AppData\Local\Programs\Python\Python38-32\lib\site-packages\django\core\handlers\base.py", line 113, in _get_response
    response = wrapped_callback(request, *callback_args, **callback_kwargs)
  File "C:\Users\equihua\AppData\Local\Programs\Python\Python38-32\lib\site-packages\django\views\decorators\csrf.py", line 54, in wrapped_view
    return view_func(*args, **kwargs)
  File "C:\Users\equihua\AppData\Local\Programs\Python\Python38-32\lib\site-packages\django\views\generic\base.py", line 71, in view
    return self.dispatch(request, *args, **kwargs)
  File "C:\Users\equihua\AppData\Local\Programs\Python\Python38-32\lib\site-packages\rest_framework\views.py", line 505, in dispatch
    response = self.handle_exception(exc)
  File "C:\Users\equihua\AppData\Local\Programs\Python\Python38-32\lib\site-packages\rest_framework\views.py", line 465, in handle_exception
    self.raise_uncaught_exception(exc)
  File "C:\Users\equihua\AppData\Local\Programs\Python\Python38-32\lib\site-packages\rest_framework\views.py", line 476, in raise_uncaught_exception
    raise exc
  File "C:\Users\equihua\AppData\Local\Programs\Python\Python38-32\lib\site-packages\rest_framework\views.py", line 502, in dispatch
    response = handler(request, *args, **kwargs)
  File "C:\Users\equihua\AppData\Local\Programs\Python\Python38-32\lib\site-packages\rest_framework\decorators.py", line 50, in handler
    return func(*args, **kwargs)
  File "C:\Users\equihua\Documents\testfacturedo\rssreader\rssapp\api.py", line 213, in get_channel_users
    channels_exclude_ids = RssChannel.objects.exclude(id__in=channels_ids)
  File "C:\Users\equihua\AppData\Local\Programs\Python\Python38-32\lib\site-packages\django\db\models\manager.py", line 82, in manager_method
    return getattr(self.get_queryset(), name)(*args, **kwargs)
  File "C:\Users\equihua\AppData\Local\Programs\Python\Python38-32\lib\site-packages\django\db\models\query.py", line 899, in exclude
    return self._filter_or_exclude(True, *args, **kwargs)
  File "C:\Users\equihua\AppData\Local\Programs\Python\Python38-32\lib\site-packages\django\db\models\query.py", line 908, in _filter_or_exclude
    clone.query.add_q(~Q(*args, **kwargs))
  File "C:\Users\equihua\AppData\Local\Programs\Python\Python38-32\lib\site-packages\django\db\models\sql\query.py", line 1290, in add_q
    clause, _ = self._add_q(q_object, self.used_aliases)
  File "C:\Users\equihua\AppData\Local\Programs\Python\Python38-32\lib\site-packages\django\db\models\sql\query.py", line 1315, in _add_q
    child_clause, needed_inner = self.build_filter(
  File "C:\Users\equihua\AppData\Local\Programs\Python\Python38-32\lib\site-packages\django\db\models\sql\query.py", line 1251, in build_filter
    condition = self.build_lookup(lookups, col, value)
  File "C:\Users\equihua\AppData\Local\Programs\Python\Python38-32\lib\site-packages\django\db\models\sql\query.py", line 1116, in build_lookup
    lookup = lookup_class(lhs, rhs)
  File "C:\Users\equihua\AppData\Local\Programs\Python\Python38-32\lib\site-packages\django\db\models\lookups.py", line 20, in __init__
    self.rhs = self.get_prep_lookup()
  File "C:\Users\equihua\AppData\Local\Programs\Python\Python38-32\lib\site-packages\django\db\models\lookups.py", line 204, in get_prep_lookup
    for rhs_value in self.rhs:
TypeError: 'ManyRelatedManager' object is not iterable
"POST /api/rss/chanles/users/ HTTP/1.1" 500 18777
Internal Server Error: /api/rss/chanles/users/
Traceback (most recent call last):
  File "C:\Users\equihua\AppData\Local\Programs\Python\Python38-32\lib\site-packages\django\core\handlers\exception.py", line 34, in inner
    response = get_response(request)
  File "C:\Users\equihua\AppData\Local\Programs\Python\Python38-32\lib\site-packages\django\core\handlers\base.py", line 115, in _get_response
    response = self.process_exception_by_middleware(e, request)
  File "C:\Users\equihua\AppData\Local\Programs\Python\Python38-32\lib\site-packages\django\core\handlers\base.py", line 113, in _get_response
    response = wrapped_callback(request, *callback_args, **callback_kwargs)
  File "C:\Users\equihua\AppData\Local\Programs\Python\Python38-32\lib\site-packages\django\views\decorators\csrf.py", line 54, in wrapped_view
    return view_func(*args, **kwargs)
  File "C:\Users\equihua\AppData\Local\Programs\Python\Python38-32\lib\site-packages\django\views\generic\base.py", line 71, in view
    return self.dispatch(request, *args, **kwargs)
  File "C:\Users\equihua\AppData\Local\Programs\Python\Python38-32\lib\site-packages\rest_framework\views.py", line 505, in dispatch
    response = self.handle_exception(exc)
  File "C:\Users\equihua\AppData\Local\Programs\Python\Python38-32\lib\site-packages\rest_framework\views.py", line 465, in handle_exception
    self.raise_uncaught_exception(exc)
  File "C:\Users\equihua\AppData\Local\Programs\Python\Python38-32\lib\site-packages\rest_framework\views.py", line 476, in raise_uncaught_exception
    raise exc
  File "C:\Users\equihua\AppData\Local\Programs\Python\Python38-32\lib\site-packages\rest_framework\views.py", line 502, in dispatch
    response = handler(request, *args, **kwargs)
  File "C:\Users\equihua\AppData\Local\Programs\Python\Python38-32\lib\site-packages\rest_framework\decorators.py", line 50, in handler
    return func(*args, **kwargs)
  File "C:\Users\equihua\Documents\testfacturedo\rssreader\rssapp\api.py", line 213, in get_channel_users
    channels_exclude_ids = RssChannel.objects.exclude(id__in=channels_ids)
  File "C:\Users\equihua\AppData\Local\Programs\Python\Python38-32\lib\site-packages\django\db\models\manager.py", line 82, in manager_method
    return getattr(self.get_queryset(), name)(*args, **kwargs)
  File "C:\Users\equihua\AppData\Local\Programs\Python\Python38-32\lib\site-packages\django\db\models\query.py", line 899, in exclude
    return self._filter_or_exclude(True, *args, **kwargs)
  File "C:\Users\equihua\AppData\Local\Programs\Python\Python38-32\lib\site-packages\django\db\models\query.py", line 908, in _filter_or_exclude
    clone.query.add_q(~Q(*args, **kwargs))
  File "C:\Users\equihua\AppData\Local\Programs\Python\Python38-32\lib\site-packages\django\db\models\sql\query.py", line 1290, in add_q
    clause, _ = self._add_q(q_object, self.used_aliases)
  File "C:\Users\equihua\AppData\Local\Programs\Python\Python38-32\lib\site-packages\django\db\models\sql\query.py", line 1315, in _add_q
    child_clause, needed_inner = self.build_filter(
  File "C:\Users\equihua\AppData\Local\Programs\Python\Python38-32\lib\site-packages\django\db\models\sql\query.py", line 1251, in build_filter
    condition = self.build_lookup(lookups, col, value)
  File "C:\Users\equihua\AppData\Local\Programs\Python\Python38-32\lib\site-packages\django\db\models\sql\query.py", line 1116, in build_lookup
    lookup = lookup_class(lhs, rhs)
  File "C:\Users\equihua\AppData\Local\Programs\Python\Python38-32\lib\site-packages\django\db\models\lookups.py", line 20, in __init__
    self.rhs = self.get_prep_lookup()
  File "C:\Users\equihua\AppData\Local\Programs\Python\Python38-32\lib\site-packages\django\db\models\lookups.py", line 204, in get_prep_lookup
    for rhs_value in self.rhs:
TypeError: 'ManyRelatedManager' object is not iterable
"POST /api/rss/chanles/users/ HTTP/1.1" 500 18777
Internal Server Error: /api/rss/chanles/users/
Traceback (most recent call last):
  File "C:\Users\equihua\AppData\Local\Programs\Python\Python38-32\lib\site-packages\django\core\handlers\exception.py", line 34, in inner
    response = get_response(request)
  File "C:\Users\equihua\AppData\Local\Programs\Python\Python38-32\lib\site-packages\django\core\handlers\base.py", line 115, in _get_response
    response = self.process_exception_by_middleware(e, request)
  File "C:\Users\equihua\AppData\Local\Programs\Python\Python38-32\lib\site-packages\django\core\handlers\base.py", line 113, in _get_response
    response = wrapped_callback(request, *callback_args, **callback_kwargs)
  File "C:\Users\equihua\AppData\Local\Programs\Python\Python38-32\lib\site-packages\django\views\decorators\csrf.py", line 54, in wrapped_view
    return view_func(*args, **kwargs)
  File "C:\Users\equihua\AppData\Local\Programs\Python\Python38-32\lib\site-packages\django\views\generic\base.py", line 71, in view
    return self.dispatch(request, *args, **kwargs)
  File "C:\Users\equihua\AppData\Local\Programs\Python\Python38-32\lib\site-packages\rest_framework\views.py", line 505, in dispatch
    response = self.handle_exception(exc)
  File "C:\Users\equihua\AppData\Local\Programs\Python\Python38-32\lib\site-packages\rest_framework\views.py", line 465, in handle_exception
    self.raise_uncaught_exception(exc)
  File "C:\Users\equihua\AppData\Local\Programs\Python\Python38-32\lib\site-packages\rest_framework\views.py", line 476, in raise_uncaught_exception
    raise exc
  File "C:\Users\equihua\AppData\Local\Programs\Python\Python38-32\lib\site-packages\rest_framework\views.py", line 502, in dispatch
    response = handler(request, *args, **kwargs)
  File "C:\Users\equihua\AppData\Local\Programs\Python\Python38-32\lib\site-packages\rest_framework\decorators.py", line 50, in handler
    return func(*args, **kwargs)
  File "C:\Users\equihua\Documents\testfacturedo\rssreader\rssapp\api.py", line 213, in get_channel_users
    channels_exclude_ids = RssChannel.objects.exclude(id__in=channels_ids)
  File "C:\Users\equihua\AppData\Local\Programs\Python\Python38-32\lib\site-packages\django\db\models\manager.py", line 82, in manager_method
    return getattr(self.get_queryset(), name)(*args, **kwargs)
  File "C:\Users\equihua\AppData\Local\Programs\Python\Python38-32\lib\site-packages\django\db\models\query.py", line 899, in exclude
    return self._filter_or_exclude(True, *args, **kwargs)
  File "C:\Users\equihua\AppData\Local\Programs\Python\Python38-32\lib\site-packages\django\db\models\query.py", line 908, in _filter_or_exclude
    clone.query.add_q(~Q(*args, **kwargs))
  File "C:\Users\equihua\AppData\Local\Programs\Python\Python38-32\lib\site-packages\django\db\models\sql\query.py", line 1290, in add_q
    clause, _ = self._add_q(q_object, self.used_aliases)
  File "C:\Users\equihua\AppData\Local\Programs\Python\Python38-32\lib\site-packages\django\db\models\sql\query.py", line 1315, in _add_q
    child_clause, needed_inner = self.build_filter(
  File "C:\Users\equihua\AppData\Local\Programs\Python\Python38-32\lib\site-packages\django\db\models\sql\query.py", line 1251, in build_filter
    condition = self.build_lookup(lookups, col, value)
  File "C:\Users\equihua\AppData\Local\Programs\Python\Python38-32\lib\site-packages\django\db\models\sql\query.py", line 1116, in build_lookup
    lookup = lookup_class(lhs, rhs)
  File "C:\Users\equihua\AppData\Local\Programs\Python\Python38-32\lib\site-packages\django\db\models\lookups.py", line 20, in __init__
    self.rhs = self.get_prep_lookup()
  File "C:\Users\equihua\AppData\Local\Programs\Python\Python38-32\lib\site-packages\django\db\models\lookups.py", line 204, in get_prep_lookup
    for rhs_value in self.rhs:
TypeError: 'ManyRelatedManager' object is not iterable
"POST /api/rss/chanles/users/ HTTP/1.1" 500 18777
Internal Server Error: /api/rss/chanles/users/
Traceback (most recent call last):
  File "C:\Users\equihua\AppData\Local\Programs\Python\Python38-32\lib\site-packages\django\core\handlers\exception.py", line 34, in inner
    response = get_response(request)
  File "C:\Users\equihua\AppData\Local\Programs\Python\Python38-32\lib\site-packages\django\core\handlers\base.py", line 115, in _get_response
    response = self.process_exception_by_middleware(e, request)
  File "C:\Users\equihua\AppData\Local\Programs\Python\Python38-32\lib\site-packages\django\core\handlers\base.py", line 113, in _get_response
    response = wrapped_callback(request, *callback_args, **callback_kwargs)
  File "C:\Users\equihua\AppData\Local\Programs\Python\Python38-32\lib\site-packages\django\views\decorators\csrf.py", line 54, in wrapped_view
    return view_func(*args, **kwargs)
  File "C:\Users\equihua\AppData\Local\Programs\Python\Python38-32\lib\site-packages\django\views\generic\base.py", line 71, in view
    return self.dispatch(request, *args, **kwargs)
  File "C:\Users\equihua\AppData\Local\Programs\Python\Python38-32\lib\site-packages\rest_framework\views.py", line 505, in dispatch
    response = self.handle_exception(exc)
  File "C:\Users\equihua\AppData\Local\Programs\Python\Python38-32\lib\site-packages\rest_framework\views.py", line 465, in handle_exception
    self.raise_uncaught_exception(exc)
  File "C:\Users\equihua\AppData\Local\Programs\Python\Python38-32\lib\site-packages\rest_framework\views.py", line 476, in raise_uncaught_exception
    raise exc
  File "C:\Users\equihua\AppData\Local\Programs\Python\Python38-32\lib\site-packages\rest_framework\views.py", line 502, in dispatch
    response = handler(request, *args, **kwargs)
  File "C:\Users\equihua\AppData\Local\Programs\Python\Python38-32\lib\site-packages\rest_framework\decorators.py", line 50, in handler
    return func(*args, **kwargs)
  File "C:\Users\equihua\Documents\testfacturedo\rssreader\rssapp\api.py", line 214, in get_channel_users
    channels_exclude_ids = RssChannel.objects.exclude(id__in=channels_ids)
  File "C:\Users\equihua\AppData\Local\Programs\Python\Python38-32\lib\site-packages\django\db\models\manager.py", line 82, in manager_method
    return getattr(self.get_queryset(), name)(*args, **kwargs)
  File "C:\Users\equihua\AppData\Local\Programs\Python\Python38-32\lib\site-packages\django\db\models\query.py", line 899, in exclude
    return self._filter_or_exclude(True, *args, **kwargs)
  File "C:\Users\equihua\AppData\Local\Programs\Python\Python38-32\lib\site-packages\django\db\models\query.py", line 908, in _filter_or_exclude
    clone.query.add_q(~Q(*args, **kwargs))
  File "C:\Users\equihua\AppData\Local\Programs\Python\Python38-32\lib\site-packages\django\db\models\sql\query.py", line 1290, in add_q
    clause, _ = self._add_q(q_object, self.used_aliases)
  File "C:\Users\equihua\AppData\Local\Programs\Python\Python38-32\lib\site-packages\django\db\models\sql\query.py", line 1315, in _add_q
    child_clause, needed_inner = self.build_filter(
  File "C:\Users\equihua\AppData\Local\Programs\Python\Python38-32\lib\site-packages\django\db\models\sql\query.py", line 1251, in build_filter
    condition = self.build_lookup(lookups, col, value)
  File "C:\Users\equihua\AppData\Local\Programs\Python\Python38-32\lib\site-packages\django\db\models\sql\query.py", line 1116, in build_lookup
    lookup = lookup_class(lhs, rhs)
  File "C:\Users\equihua\AppData\Local\Programs\Python\Python38-32\lib\site-packages\django\db\models\lookups.py", line 20, in __init__
    self.rhs = self.get_prep_lookup()
  File "C:\Users\equihua\AppData\Local\Programs\Python\Python38-32\lib\site-packages\django\db\models\lookups.py", line 204, in get_prep_lookup
    for rhs_value in self.rhs:
TypeError: 'ManyRelatedManager' object is not iterable
"POST /api/rss/chanles/users/ HTTP/1.1" 500 18777
Internal Server Error: /api/rss/chanles/users/
Traceback (most recent call last):
  File "C:\Users\equihua\AppData\Local\Programs\Python\Python38-32\lib\site-packages\django\core\handlers\exception.py", line 34, in inner
    response = get_response(request)
  File "C:\Users\equihua\AppData\Local\Programs\Python\Python38-32\lib\site-packages\django\core\handlers\base.py", line 115, in _get_response
    response = self.process_exception_by_middleware(e, request)
  File "C:\Users\equihua\AppData\Local\Programs\Python\Python38-32\lib\site-packages\django\core\handlers\base.py", line 113, in _get_response
    response = wrapped_callback(request, *callback_args, **callback_kwargs)
  File "C:\Users\equihua\AppData\Local\Programs\Python\Python38-32\lib\site-packages\django\views\decorators\csrf.py", line 54, in wrapped_view
    return view_func(*args, **kwargs)
  File "C:\Users\equihua\AppData\Local\Programs\Python\Python38-32\lib\site-packages\django\views\generic\base.py", line 71, in view
    return self.dispatch(request, *args, **kwargs)
  File "C:\Users\equihua\AppData\Local\Programs\Python\Python38-32\lib\site-packages\rest_framework\views.py", line 505, in dispatch
    response = self.handle_exception(exc)
  File "C:\Users\equihua\AppData\Local\Programs\Python\Python38-32\lib\site-packages\rest_framework\views.py", line 465, in handle_exception
    self.raise_uncaught_exception(exc)
  File "C:\Users\equihua\AppData\Local\Programs\Python\Python38-32\lib\site-packages\rest_framework\views.py", line 476, in raise_uncaught_exception
    raise exc
  File "C:\Users\equihua\AppData\Local\Programs\Python\Python38-32\lib\site-packages\rest_framework\views.py", line 502, in dispatch
    response = handler(request, *args, **kwargs)
  File "C:\Users\equihua\AppData\Local\Programs\Python\Python38-32\lib\site-packages\rest_framework\decorators.py", line 50, in handler
    return func(*args, **kwargs)
  File "C:\Users\equihua\Documents\testfacturedo\rssreader\rssapp\api.py", line 215, in get_channel_users
    channels_exclude_ids = RssChannel.objects.exclude(id__in=channels_ids)
  File "C:\Users\equihua\AppData\Local\Programs\Python\Python38-32\lib\site-packages\django\db\models\manager.py", line 82, in manager_method
    return getattr(self.get_queryset(), name)(*args, **kwargs)
  File "C:\Users\equihua\AppData\Local\Programs\Python\Python38-32\lib\site-packages\django\db\models\query.py", line 899, in exclude
    return self._filter_or_exclude(True, *args, **kwargs)
  File "C:\Users\equihua\AppData\Local\Programs\Python\Python38-32\lib\site-packages\django\db\models\query.py", line 908, in _filter_or_exclude
    clone.query.add_q(~Q(*args, **kwargs))
  File "C:\Users\equihua\AppData\Local\Programs\Python\Python38-32\lib\site-packages\django\db\models\sql\query.py", line 1290, in add_q
    clause, _ = self._add_q(q_object, self.used_aliases)
  File "C:\Users\equihua\AppData\Local\Programs\Python\Python38-32\lib\site-packages\django\db\models\sql\query.py", line 1315, in _add_q
    child_clause, needed_inner = self.build_filter(
  File "C:\Users\equihua\AppData\Local\Programs\Python\Python38-32\lib\site-packages\django\db\models\sql\query.py", line 1251, in build_filter
    condition = self.build_lookup(lookups, col, value)
  File "C:\Users\equihua\AppData\Local\Programs\Python\Python38-32\lib\site-packages\django\db\models\sql\query.py", line 1116, in build_lookup
    lookup = lookup_class(lhs, rhs)
  File "C:\Users\equihua\AppData\Local\Programs\Python\Python38-32\lib\site-packages\django\db\models\lookups.py", line 20, in __init__
    self.rhs = self.get_prep_lookup()
  File "C:\Users\equihua\AppData\Local\Programs\Python\Python38-32\lib\site-packages\django\db\models\lookups.py", line 204, in get_prep_lookup
    for rhs_value in self.rhs:
TypeError: 'ManyRelatedManager' object is not iterable
"POST /api/rss/chanles/users/ HTTP/1.1" 500 18781
Internal Server Error: /api/rss/chanles/users/
Traceback (most recent call last):
  File "C:\Users\equihua\AppData\Local\Programs\Python\Python38-32\lib\site-packages\django\core\handlers\exception.py", line 34, in inner
    response = get_response(request)
  File "C:\Users\equihua\AppData\Local\Programs\Python\Python38-32\lib\site-packages\django\core\handlers\base.py", line 115, in _get_response
    response = self.process_exception_by_middleware(e, request)
  File "C:\Users\equihua\AppData\Local\Programs\Python\Python38-32\lib\site-packages\django\core\handlers\base.py", line 113, in _get_response
    response = wrapped_callback(request, *callback_args, **callback_kwargs)
  File "C:\Users\equihua\AppData\Local\Programs\Python\Python38-32\lib\site-packages\django\views\decorators\csrf.py", line 54, in wrapped_view
    return view_func(*args, **kwargs)
  File "C:\Users\equihua\AppData\Local\Programs\Python\Python38-32\lib\site-packages\django\views\generic\base.py", line 71, in view
    return self.dispatch(request, *args, **kwargs)
  File "C:\Users\equihua\AppData\Local\Programs\Python\Python38-32\lib\site-packages\rest_framework\views.py", line 505, in dispatch
    response = self.handle_exception(exc)
  File "C:\Users\equihua\AppData\Local\Programs\Python\Python38-32\lib\site-packages\rest_framework\views.py", line 465, in handle_exception
    self.raise_uncaught_exception(exc)
  File "C:\Users\equihua\AppData\Local\Programs\Python\Python38-32\lib\site-packages\rest_framework\views.py", line 476, in raise_uncaught_exception
    raise exc
  File "C:\Users\equihua\AppData\Local\Programs\Python\Python38-32\lib\site-packages\rest_framework\views.py", line 502, in dispatch
    response = handler(request, *args, **kwargs)
  File "C:\Users\equihua\AppData\Local\Programs\Python\Python38-32\lib\site-packages\rest_framework\decorators.py", line 50, in handler
    return func(*args, **kwargs)
  File "C:\Users\equihua\Documents\testfacturedo\rssreader\rssapp\api.py", line 213, in get_channel_users
    print(channels_ids.ids)
AttributeError: 'ManyRelatedManager' object has no attribute 'ids'
"POST /api/rss/chanles/users/ HTTP/1.1" 500 17046
Internal Server Error: /api/rss/chanles/users/
Traceback (most recent call last):
  File "C:\Users\equihua\AppData\Local\Programs\Python\Python38-32\lib\site-packages\django\db\backends\utils.py", line 84, in _execute
    return self.cursor.execute(sql, params)
  File "C:\Users\equihua\AppData\Local\Programs\Python\Python38-32\lib\site-packages\django\db\backends\sqlite3\base.py", line 383, in execute
    return Database.Cursor.execute(self, query, params)
sqlite3.ProgrammingError: Incorrect number of bindings supplied. The current statement uses 2, and there are 1 supplied.

The above exception was the direct cause of the following exception:

Traceback (most recent call last):
  File "C:\Users\equihua\AppData\Local\Programs\Python\Python38-32\lib\site-packages\django\db\backends\utils.py", line 99, in execute
    return super().execute(sql, params)
  File "C:\Users\equihua\AppData\Local\Programs\Python\Python38-32\lib\site-packages\django\db\backends\utils.py", line 67, in execute
    return self._execute_with_wrappers(sql, params, many=False, executor=self._execute)
  File "C:\Users\equihua\AppData\Local\Programs\Python\Python38-32\lib\site-packages\django\db\backends\utils.py", line 76, in _execute_with_wrappers
    return executor(sql, params, many, context)
  File "C:\Users\equihua\AppData\Local\Programs\Python\Python38-32\lib\site-packages\django\db\backends\utils.py", line 84, in _execute
    return self.cursor.execute(sql, params)
  File "C:\Users\equihua\AppData\Local\Programs\Python\Python38-32\lib\site-packages\django\db\utils.py", line 89, in __exit__
    raise dj_exc_value.with_traceback(traceback) from exc_value
  File "C:\Users\equihua\AppData\Local\Programs\Python\Python38-32\lib\site-packages\django\db\backends\utils.py", line 84, in _execute
    return self.cursor.execute(sql, params)
  File "C:\Users\equihua\AppData\Local\Programs\Python\Python38-32\lib\site-packages\django\db\backends\sqlite3\base.py", line 383, in execute
    return Database.Cursor.execute(self, query, params)
django.db.utils.ProgrammingError: Incorrect number of bindings supplied. The current statement uses 2, and there are 1 supplied.

During handling of the above exception, another exception occurred:

Traceback (most recent call last):
  File "C:\Users\equihua\AppData\Local\Programs\Python\Python38-32\lib\site-packages\django\core\handlers\exception.py", line 34, in inner
    response = get_response(request)
  File "C:\Users\equihua\AppData\Local\Programs\Python\Python38-32\lib\site-packages\django\core\handlers\base.py", line 115, in _get_response
    response = self.process_exception_by_middleware(e, request)
  File "C:\Users\equihua\AppData\Local\Programs\Python\Python38-32\lib\site-packages\django\core\handlers\base.py", line 113, in _get_response
    response = wrapped_callback(request, *callback_args, **callback_kwargs)
  File "C:\Users\equihua\AppData\Local\Programs\Python\Python38-32\lib\site-packages\django\views\decorators\csrf.py", line 54, in wrapped_view
    return view_func(*args, **kwargs)
  File "C:\Users\equihua\AppData\Local\Programs\Python\Python38-32\lib\site-packages\django\views\generic\base.py", line 71, in view
    return self.dispatch(request, *args, **kwargs)
  File "C:\Users\equihua\AppData\Local\Programs\Python\Python38-32\lib\site-packages\rest_framework\views.py", line 505, in dispatch
    response = self.handle_exception(exc)
  File "C:\Users\equihua\AppData\Local\Programs\Python\Python38-32\lib\site-packages\rest_framework\views.py", line 465, in handle_exception
    self.raise_uncaught_exception(exc)
  File "C:\Users\equihua\AppData\Local\Programs\Python\Python38-32\lib\site-packages\rest_framework\views.py", line 476, in raise_uncaught_exception
    raise exc
  File "C:\Users\equihua\AppData\Local\Programs\Python\Python38-32\lib\site-packages\rest_framework\views.py", line 502, in dispatch
    response = handler(request, *args, **kwargs)
  File "C:\Users\equihua\AppData\Local\Programs\Python\Python38-32\lib\site-packages\rest_framework\decorators.py", line 50, in handler
    return func(*args, **kwargs)
  File "C:\Users\equihua\Documents\testfacturedo\rssreader\rssapp\api.py", line 215, in get_channel_users
    cursor.execute("""
  File "C:\Users\equihua\AppData\Local\Programs\Python\Python38-32\lib\site-packages\django\db\backends\utils.py", line 103, in execute
    sql = self.db.ops.last_executed_query(self.cursor, sql, params)
  File "C:\Users\equihua\AppData\Local\Programs\Python\Python38-32\lib\site-packages\django\db\backends\sqlite3\operations.py", line 155, in last_executed_query
    return sql % params
TypeError: not enough arguments for format string
"POST /api/rss/chanles/users/ HTTP/1.1" 500 19487
Internal Server Error: /api/rss/chanles/users/
Traceback (most recent call last):
  File "C:\Users\equihua\AppData\Local\Programs\Python\Python38-32\lib\site-packages\django\db\backends\utils.py", line 84, in _execute
    return self.cursor.execute(sql, params)
  File "C:\Users\equihua\AppData\Local\Programs\Python\Python38-32\lib\site-packages\django\db\backends\sqlite3\base.py", line 383, in execute
    return Database.Cursor.execute(self, query, params)
sqlite3.ProgrammingError: Incorrect number of bindings supplied. The current statement uses 2, and there are 1 supplied.

The above exception was the direct cause of the following exception:

Traceback (most recent call last):
  File "C:\Users\equihua\AppData\Local\Programs\Python\Python38-32\lib\site-packages\django\db\backends\utils.py", line 99, in execute
    return super().execute(sql, params)
  File "C:\Users\equihua\AppData\Local\Programs\Python\Python38-32\lib\site-packages\django\db\backends\utils.py", line 67, in execute
    return self._execute_with_wrappers(sql, params, many=False, executor=self._execute)
  File "C:\Users\equihua\AppData\Local\Programs\Python\Python38-32\lib\site-packages\django\db\backends\utils.py", line 76, in _execute_with_wrappers
    return executor(sql, params, many, context)
  File "C:\Users\equihua\AppData\Local\Programs\Python\Python38-32\lib\site-packages\django\db\backends\utils.py", line 84, in _execute
    return self.cursor.execute(sql, params)
  File "C:\Users\equihua\AppData\Local\Programs\Python\Python38-32\lib\site-packages\django\db\utils.py", line 89, in __exit__
    raise dj_exc_value.with_traceback(traceback) from exc_value
  File "C:\Users\equihua\AppData\Local\Programs\Python\Python38-32\lib\site-packages\django\db\backends\utils.py", line 84, in _execute
    return self.cursor.execute(sql, params)
  File "C:\Users\equihua\AppData\Local\Programs\Python\Python38-32\lib\site-packages\django\db\backends\sqlite3\base.py", line 383, in execute
    return Database.Cursor.execute(self, query, params)
django.db.utils.ProgrammingError: Incorrect number of bindings supplied. The current statement uses 2, and there are 1 supplied.

During handling of the above exception, another exception occurred:

Traceback (most recent call last):
  File "C:\Users\equihua\AppData\Local\Programs\Python\Python38-32\lib\site-packages\django\core\handlers\exception.py", line 34, in inner
    response = get_response(request)
  File "C:\Users\equihua\AppData\Local\Programs\Python\Python38-32\lib\site-packages\django\core\handlers\base.py", line 115, in _get_response
    response = self.process_exception_by_middleware(e, request)
  File "C:\Users\equihua\AppData\Local\Programs\Python\Python38-32\lib\site-packages\django\core\handlers\base.py", line 113, in _get_response
    response = wrapped_callback(request, *callback_args, **callback_kwargs)
  File "C:\Users\equihua\AppData\Local\Programs\Python\Python38-32\lib\site-packages\django\views\decorators\csrf.py", line 54, in wrapped_view
    return view_func(*args, **kwargs)
  File "C:\Users\equihua\AppData\Local\Programs\Python\Python38-32\lib\site-packages\django\views\generic\base.py", line 71, in view
    return self.dispatch(request, *args, **kwargs)
  File "C:\Users\equihua\AppData\Local\Programs\Python\Python38-32\lib\site-packages\rest_framework\views.py", line 505, in dispatch
    response = self.handle_exception(exc)
  File "C:\Users\equihua\AppData\Local\Programs\Python\Python38-32\lib\site-packages\rest_framework\views.py", line 465, in handle_exception
    self.raise_uncaught_exception(exc)
  File "C:\Users\equihua\AppData\Local\Programs\Python\Python38-32\lib\site-packages\rest_framework\views.py", line 476, in raise_uncaught_exception
    raise exc
  File "C:\Users\equihua\AppData\Local\Programs\Python\Python38-32\lib\site-packages\rest_framework\views.py", line 502, in dispatch
    response = handler(request, *args, **kwargs)
  File "C:\Users\equihua\AppData\Local\Programs\Python\Python38-32\lib\site-packages\rest_framework\decorators.py", line 50, in handler
    return func(*args, **kwargs)
  File "C:\Users\equihua\Documents\testfacturedo\rssreader\rssapp\api.py", line 215, in get_channel_users
    cursor.execute("""
  File "C:\Users\equihua\AppData\Local\Programs\Python\Python38-32\lib\site-packages\django\db\backends\utils.py", line 103, in execute
    sql = self.db.ops.last_executed_query(self.cursor, sql, params)
  File "C:\Users\equihua\AppData\Local\Programs\Python\Python38-32\lib\site-packages\django\db\backends\sqlite3\operations.py", line 155, in last_executed_query
    return sql % params
TypeError: not enough arguments for format string
"POST /api/rss/chanles/users/ HTTP/1.1" 500 19487
Internal Server Error: /
Traceback (most recent call last):
  File "C:\Users\equihua\AppData\Local\Programs\Python\Python38-32\lib\site-packages\django\template\smartif.py", line 175, in translate_token
    op = OPERATORS[token]
KeyError: '${item.added}'

During handling of the above exception, another exception occurred:

Traceback (most recent call last):
  File "C:\Users\equihua\AppData\Local\Programs\Python\Python38-32\lib\site-packages\django\core\handlers\exception.py", line 34, in inner
    response = get_response(request)
  File "C:\Users\equihua\AppData\Local\Programs\Python\Python38-32\lib\site-packages\django\core\handlers\base.py", line 115, in _get_response
    response = self.process_exception_by_middleware(e, request)
  File "C:\Users\equihua\AppData\Local\Programs\Python\Python38-32\lib\site-packages\django\core\handlers\base.py", line 113, in _get_response
    response = wrapped_callback(request, *callback_args, **callback_kwargs)
  File "C:\Users\equihua\Documents\testfacturedo\rssreader\rssapp\views.py", line 12, in index_view
    return render(request, "index.html", ctx)
  File "C:\Users\equihua\AppData\Local\Programs\Python\Python38-32\lib\site-packages\django\shortcuts.py", line 36, in render
    content = loader.render_to_string(template_name, context, request, using=using)
  File "C:\Users\equihua\AppData\Local\Programs\Python\Python38-32\lib\site-packages\django\template\loader.py", line 61, in render_to_string
    template = get_template(template_name, using=using)
  File "C:\Users\equihua\AppData\Local\Programs\Python\Python38-32\lib\site-packages\django\template\loader.py", line 15, in get_template
    return engine.get_template(template_name)
  File "C:\Users\equihua\AppData\Local\Programs\Python\Python38-32\lib\site-packages\django\template\backends\django.py", line 34, in get_template
    return Template(self.engine.get_template(template_name), self)
  File "C:\Users\equihua\AppData\Local\Programs\Python\Python38-32\lib\site-packages\django\template\engine.py", line 143, in get_template
    template, origin = self.find_template(template_name)
  File "C:\Users\equihua\AppData\Local\Programs\Python\Python38-32\lib\site-packages\django\template\engine.py", line 125, in find_template
    template = loader.get_template(name, skip=skip)
  File "C:\Users\equihua\AppData\Local\Programs\Python\Python38-32\lib\site-packages\django\template\loaders\base.py", line 29, in get_template
    return Template(
  File "C:\Users\equihua\AppData\Local\Programs\Python\Python38-32\lib\site-packages\django\template\base.py", line 156, in __init__
    self.nodelist = self.compile_nodelist()
  File "C:\Users\equihua\AppData\Local\Programs\Python\Python38-32\lib\site-packages\django\template\base.py", line 194, in compile_nodelist
    return parser.parse()
  File "C:\Users\equihua\AppData\Local\Programs\Python\Python38-32\lib\site-packages\django\template\base.py", line 478, in parse
    raise self.error(token, e)
  File "C:\Users\equihua\AppData\Local\Programs\Python\Python38-32\lib\site-packages\django\template\base.py", line 476, in parse
    compiled_result = compile_func(self, token)
  File "C:\Users\equihua\AppData\Local\Programs\Python\Python38-32\lib\site-packages\django\template\defaulttags.py", line 951, in do_if
    condition = TemplateIfParser(parser, bits).parse()
  File "C:\Users\equihua\AppData\Local\Programs\Python\Python38-32\lib\site-packages\django\template\defaulttags.py", line 884, in __init__
    super().__init__(*args, **kwargs)
  File "C:\Users\equihua\AppData\Local\Programs\Python\Python38-32\lib\site-packages\django\template\smartif.py", line 166, in __init__
    mapped_tokens.append(self.translate_token(token))
  File "C:\Users\equihua\AppData\Local\Programs\Python\Python38-32\lib\site-packages\django\template\smartif.py", line 177, in translate_token
    return self.create_var(token)
  File "C:\Users\equihua\AppData\Local\Programs\Python\Python38-32\lib\site-packages\django\template\defaulttags.py", line 887, in create_var
    return TemplateLiteral(self.template_parser.compile_filter(value), value)
  File "C:\Users\equihua\AppData\Local\Programs\Python\Python38-32\lib\site-packages\django\template\base.py", line 563, in compile_filter
    return FilterExpression(token, self)
  File "C:\Users\equihua\AppData\Local\Programs\Python\Python38-32\lib\site-packages\django\template\base.py", line 662, in __init__
    raise TemplateSyntaxError("Could not parse the remainder: '%s' "
django.template.exceptions.TemplateSyntaxError: Could not parse the remainder: '${item.added}' from '${item.added}'
"GET / HTTP/1.1" 500 166423
Internal Server Error: /
Traceback (most recent call last):
  File "C:\Users\equihua\AppData\Local\Programs\Python\Python38-32\lib\site-packages\django\template\smartif.py", line 175, in translate_token
    op = OPERATORS[token]
KeyError: '${item.added}'

During handling of the above exception, another exception occurred:

Traceback (most recent call last):
  File "C:\Users\equihua\AppData\Local\Programs\Python\Python38-32\lib\site-packages\django\core\handlers\exception.py", line 34, in inner
    response = get_response(request)
  File "C:\Users\equihua\AppData\Local\Programs\Python\Python38-32\lib\site-packages\django\core\handlers\base.py", line 115, in _get_response
    response = self.process_exception_by_middleware(e, request)
  File "C:\Users\equihua\AppData\Local\Programs\Python\Python38-32\lib\site-packages\django\core\handlers\base.py", line 113, in _get_response
    response = wrapped_callback(request, *callback_args, **callback_kwargs)
  File "C:\Users\equihua\Documents\testfacturedo\rssreader\rssapp\views.py", line 12, in index_view
    return render(request, "index.html", ctx)
  File "C:\Users\equihua\AppData\Local\Programs\Python\Python38-32\lib\site-packages\django\shortcuts.py", line 36, in render
    content = loader.render_to_string(template_name, context, request, using=using)
  File "C:\Users\equihua\AppData\Local\Programs\Python\Python38-32\lib\site-packages\django\template\loader.py", line 61, in render_to_string
    template = get_template(template_name, using=using)
  File "C:\Users\equihua\AppData\Local\Programs\Python\Python38-32\lib\site-packages\django\template\loader.py", line 15, in get_template
    return engine.get_template(template_name)
  File "C:\Users\equihua\AppData\Local\Programs\Python\Python38-32\lib\site-packages\django\template\backends\django.py", line 34, in get_template
    return Template(self.engine.get_template(template_name), self)
  File "C:\Users\equihua\AppData\Local\Programs\Python\Python38-32\lib\site-packages\django\template\engine.py", line 143, in get_template
    template, origin = self.find_template(template_name)
  File "C:\Users\equihua\AppData\Local\Programs\Python\Python38-32\lib\site-packages\django\template\engine.py", line 125, in find_template
    template = loader.get_template(name, skip=skip)
  File "C:\Users\equihua\AppData\Local\Programs\Python\Python38-32\lib\site-packages\django\template\loaders\base.py", line 29, in get_template
    return Template(
  File "C:\Users\equihua\AppData\Local\Programs\Python\Python38-32\lib\site-packages\django\template\base.py", line 156, in __init__
    self.nodelist = self.compile_nodelist()
  File "C:\Users\equihua\AppData\Local\Programs\Python\Python38-32\lib\site-packages\django\template\base.py", line 194, in compile_nodelist
    return parser.parse()
  File "C:\Users\equihua\AppData\Local\Programs\Python\Python38-32\lib\site-packages\django\template\base.py", line 478, in parse
    raise self.error(token, e)
  File "C:\Users\equihua\AppData\Local\Programs\Python\Python38-32\lib\site-packages\django\template\base.py", line 476, in parse
    compiled_result = compile_func(self, token)
  File "C:\Users\equihua\AppData\Local\Programs\Python\Python38-32\lib\site-packages\django\template\defaulttags.py", line 951, in do_if
    condition = TemplateIfParser(parser, bits).parse()
  File "C:\Users\equihua\AppData\Local\Programs\Python\Python38-32\lib\site-packages\django\template\defaulttags.py", line 884, in __init__
    super().__init__(*args, **kwargs)
  File "C:\Users\equihua\AppData\Local\Programs\Python\Python38-32\lib\site-packages\django\template\smartif.py", line 166, in __init__
    mapped_tokens.append(self.translate_token(token))
  File "C:\Users\equihua\AppData\Local\Programs\Python\Python38-32\lib\site-packages\django\template\smartif.py", line 177, in translate_token
    return self.create_var(token)
  File "C:\Users\equihua\AppData\Local\Programs\Python\Python38-32\lib\site-packages\django\template\defaulttags.py", line 887, in create_var
    return TemplateLiteral(self.template_parser.compile_filter(value), value)
  File "C:\Users\equihua\AppData\Local\Programs\Python\Python38-32\lib\site-packages\django\template\base.py", line 563, in compile_filter
    return FilterExpression(token, self)
  File "C:\Users\equihua\AppData\Local\Programs\Python\Python38-32\lib\site-packages\django\template\base.py", line 662, in __init__
    raise TemplateSyntaxError("Could not parse the remainder: '%s' "
django.template.exceptions.TemplateSyntaxError: Could not parse the remainder: '${item.added}' from '${item.added}'
"GET / HTTP/1.1" 500 166423
Internal Server Error: /api/crud/update/
"POST /api/crud/update/ HTTP/1.1" 500 34
Internal Server Error: /api/crud/update/
"POST /api/crud/update/ HTTP/1.1" 500 34
Internal Server Error: /api/crud/delete/
"POST /api/crud/delete/ HTTP/1.1" 500 34
Internal Server Error: /api/crud/delete/
"POST /api/crud/delete/ HTTP/1.1" 500 34
Internal Server Error: /api/crud/delete/
"POST /api/crud/delete/ HTTP/1.1" 500 34
Internal Server Error: /api/crud/delete/
"POST /api/crud/delete/ HTTP/1.1" 500 34
Internal Server Error: /api/rss/chanles/datasource/
"GET /api/rss/chanles/datasource/ HTTP/1.1" 500 34
Internal Server Error: /api/rss/chanles/datasource/
"GET /api/rss/chanles/datasource/ HTTP/1.1" 500 34
Internal Server Error: /api/rss/chanles/datasource/
"GET /api/rss/chanles/datasource/ HTTP/1.1" 500 34
Internal Server Error: /api/rss/chanles/datasource/
"GET /api/rss/chanles/datasource/ HTTP/1.1" 500 34
Internal Server Error: /api/rss/chanles/datasource/
"GET /api/rss/chanles/datasource/ HTTP/1.1" 500 34
Internal Server Error: /api/rss/chanles/datasource/
"GET /api/rss/chanles/datasource/ HTTP/1.1" 500 34
Internal Server Error: /api/rss/chanles/datasource/
"GET /api/rss/chanles/datasource/ HTTP/1.1" 500 34
Internal Server Error: /api/rss/chanles/datasource/
"GET /api/rss/chanles/datasource/ HTTP/1.1" 500 34
Internal Server Error: /api/rss/chanles/datasource/
"GET /api/rss/chanles/datasource/ HTTP/1.1" 500 34
Internal Server Error: /api/rss/chanles/datasource/
"GET /api/rss/chanles/datasource/ HTTP/1.1" 500 34
Internal Server Error: /api/rss/chanles/datasource/
"GET /api/rss/chanles/datasource/ HTTP/1.1" 500 34
Internal Server Error: /api/rss/chanles/datasource/
"GET /api/rss/chanles/datasource/ HTTP/1.1" 500 34
Internal Server Error: /api/rss/chanles/datasource/
"GET /api/rss/chanles/datasource/ HTTP/1.1" 500 34
Internal Server Error: /api/rss/chanles/datasource/
"GET /api/rss/chanles/datasource/ HTTP/1.1" 500 34
Internal Server Error: /api/rss/chanles/datasource/
"GET /api/rss/chanles/datasource/ HTTP/1.1" 500 34
Internal Server Error: /api/rss/chanles/datasource/
"GET /api/rss/chanles/datasource/ HTTP/1.1" 500 34
Internal Server Error: /api/rss/chanles/datasource/
"POST /api/rss/chanles/datasource/ HTTP/1.1" 500 34
Internal Server Error: /api/rss/chanles/datasource/
"POST /api/rss/chanles/datasource/ HTTP/1.1" 500 34
